Workbook

Sheet Read me
A1: Controlled car-insurance quote test
A2: Purpose: find out which answers really move the price, and which differences are just noise. Information only. Use DUMMY personal data. Never buy on a test quote.
A4: RULES
A5: 1. Use dummy details (a made-up name, a real-looking but fake date of birth and address). Do not use a real identity, and never go on to buy.
A6: 2. Fill in the 'Profile' sheet once. Keep every answer identical across all runs, except the single change being tested.
A7: 3. Change ONE thing per run. Start each run from the baseline profile again.
A8: 4. Use the same comparison site, in a private window, in one sitting (aim for under 2 hours). Prices drift by day and by time.
A9: 5. Record the cheapest price AND the insurer that gave it. If the insurer changes between runs, the gap may be the insurer, not your change.
A10: 6. Run the baseline several times (the plan has 4: start, middle, end). The spread between them is the NOISE level. Treat smaller gaps as noise.
A11: 7. Each change is planned twice. If the two runs disagree a lot, do not trust that result.
A12: 8. Use the same quote type each time. Record the cheapest comprehensive annual price with no black box, unless the row says otherwise.
A13: 9. Rows marked TEST ONLY (for example name changes) are to learn how the form behaves. Never publish them as tips and never buy on them.
... A22: Re-run at least once a quarter. Insurance prices move quickly.

Sheet Summary
A1: Summary (updates automatically)
A3: Baseline average (£/yr) | C3: =IFERROR(AVERAGE(Runs!$N$2:$N$47),"")
A4: Baseline runs recorded | C4: =COUNT(Runs!$N$2:$N$47) | D4: =IF(C4<3,"Record at least 3 baseline runs to trust the noise level.","")
A5: Noise: baseline spread (max-min)/avg | C5: =IFERROR((MAX(Runs!$N$2:$N$47)-MIN(Runs!$N$2:$N$47))/AVERAGE(Runs!$N$2:$N$47),"")
A6: Noise threshold used (larger of 5% and spread) | C6: =IF(ISNUMBER(C5),MAX(0.05,C5),0.05)
A8: Change | B8: Runs | C8: Avg price (£) | D8: Change (£) | E8: Change (%) | F8: Runs disagree by | G8: Verdict | H8: Plan note
A9: Add parent 1 as a named driver | B9: =COUNTIFS(Runs!$C$2:$C$47,A9,Runs!$G$2:$G$47,">0") | C9: =IFERROR(AVERAGEIFS(Runs!$G$2:$G$47,Runs!$C$2:$C$47,A9),"") | D9: =IF(AND(ISNUMBER(C9),ISNUMBER($C$3)),C9-$C$3,"") | E9: =IF(ISNUMBER(D9),D9/$C$3,"") | F9: =IF(B9<2,"",(SUMPRODUCT(MAX((Runs!$C$2:$C$47=A9)*(Runs!$G$2:$G$47>0)*Runs!$G$2:$G$47))-(1000000000-SUMPRODUCT(MAX((Runs!$C$2:$C$47=A9)*(Runs!$G$2:$G$47>0)*(1000000000-Runs!$G$2:$G$47)))))/C9) | G9: =IF(NOT(ISNUMBER(E9)),"No data",IF(ISNUMBER(F9),IF(F9>$C$6,"Repeats disagree: ",""),"")&IF(ABS(E9)<$C$6,"Within noise",IF(E9<0,"Cheaper","Dearer"))) | H9: Only if they would genuinely drive
A10: Add parent 2 as a named driver | B10: =COUNTIFS(Runs!$C$2:$C$47,A10,Runs!$G$2:$G$47,">0") | C10: =IFERROR(AVERAGEIFS(Runs!$G$2:$G$47,Runs!$C$2:$C$47,A10),"") | D10: =IF(AND(ISNUMBER(C10),ISNUMBER($C$3)),C10-$C$3,"") | E10: =IF(ISNUMBER(D10),D10/$C$3,"") | F10: =IF(B10<2,"",(SUMPRODUCT(MAX((Runs!$C$2:$C$47=A10)*(Runs!$G$2:$G$47>0)*Runs!$G$2:$G$47))-(1000000000-SUMPRODUCT(MAX((Runs!$C$2:$C$47=A10)*(Runs!$G$2:$G$47>0)*(1000000000-Runs!$G$2:$G$47)))))/C10) | G10: =IF(NOT(ISNUMBER(E10)),"No data",IF(ISNUMBER(F10),IF(F10>$C$6,"Repeats disagree: ",""),"")&IF(ABS(E10)<$C$6,"Within noise",IF(E10<0,"Cheaper","Dearer"))) | H10: Only if they would genuinely drive
A11: Add both parents as named drivers | B11: =COUNTIFS(Runs!$C$2:$C$47,A11,Runs!$G$2:$G$47,">0") | C11: =IFERROR(AVERAGEIFS(Runs!$G$2:$G$47,Runs!$C$2:$C$47,A11),"") | D11: =IF(AND(ISNUMBER(C11),ISNUMBER($C$3)),C11-$C$3,"") | E11: =IF(ISNUMBER(D11),D11/$C$3,"") | F11: =IF(B11<2,"",(SUMPRODUCT(MAX((Runs!$C$2:$C$47=A11)*(Runs!$G$2:$G$47>0)*Runs!$G$2:$G$47))-(1000000000-SUMPRODUCT(MAX((Runs!$C$2:$C$47=A11)*(Runs!$G$2:$G$47>0)*(1000000000-Runs!$G$2:$G$47)))))/C11) | G11: =IF(NOT(ISNUMBER(E11)),"No data",IF(ISNUMBER(F11),IF(F11>$C$6,"Repeats disagree: ",""),"")&IF(ABS(E11)<$C$6,"Within noise",IF(E11<0,"Cheaper","Dearer"))) | H11: Only if they would genuinely drive
A12: Vehicle value +10% | B12: =COUNTIFS(Runs!$C$2:$C$47,A12,Runs!$G$2:$G$47,">0") | C12: =IFERROR(AVERAGEIFS(Runs!$G$2:$G$47,Runs!$C$2:$C$47,A12),"") | D12: =IF(AND(ISNUMBER(C12),ISNUMBER($C$3)),C12-$C$3,"") | E12: =IF(ISNUMBER(D12),D12/$C$3,"") | F12: =IF(B12<2,"",(SUMPRODUCT(MAX((Runs!$C$2:$C$47=A12)*(Runs!$G$2:$G$47>0)*Runs!$G$2:$G$47))-(1000000000-SUMPRODUCT(MAX((Runs!$C$2:$C$47=A12)*(Runs!$G$2:$G$47>0)*(1000000000-Runs!$G$2:$G$47)))))/C12) | G12: =IF(NOT(ISNUMBER(E12)),"No data",IF(ISNUMBER(F12),IF(F12>$C$6,"Repeats disagree: ",""),"")&IF(ABS(E12)<$C$6,"Within noise",IF(E12<0,"Cheaper","Dearer")))
A13: Vehicle value -10% | B13: =COUNTIFS(Runs!$C$2:$C$47,A13,Runs!$G$2:$G$47,">0") | C13: =IFERROR(AVERAGEIFS(Runs!$G$2:$G$47,Runs!$C$2:$C$47,A13),"") | D13: =IF(AND(ISNUMBER(C13),ISNUMBER($C$3)),C13-$C$3,"") | E13: =IF(ISNUMBER(D13),D13/$C$3,"") | F13: =IF(B13<2,"",(SUMPRODUCT(MAX((Runs!$C$2:$C$47=A13)*(Runs!$G$2:$G$47>0)*Runs!$G$2:$G$47))-(1000000000-SUMPRODUCT(MAX((Runs!$C$2:$C$47=A13)*(Runs!$G$2:$G$47>0)*(1000000000-Runs!$G$2:$G$47)))))/C13) | G13: =IF(NOT(ISNUMBER(E13)),"No data",IF(ISNUMBER(F13),IF(F13>$C$6,"Repeats disagree: ",""),"")&IF(ABS(E13)<$C$6,"Within noise",IF(E13<0,"Cheaper","Dearer")))
A14: Add a tracker | B14: =COUNTIFS(Runs!$C$2:$C$47,A14,Runs!$G$2:$G$47,">0") | C14: =IFERROR(AVERAGEIFS(Runs!$G$2:$G$47,Runs!$C$2:$C$47,A14),"") | D14: =IF(AND(ISNUMBER(C14),ISNUMBER($C$3)),C14-$C$3,"") | E14: =IF(ISNUMBER(D14),D14/$C$3,"") | F14: =IF(B14<2,"",(SUMPRODUCT(MAX((Runs!$C$2:$C$47=A14)*(Runs!$G$2:$G$47>0)*Runs!$G$2:$G$47))-(1000000000-SUMPRODUCT(MAX((Runs!$C$2:$C$47=A14)*(Runs!$G$2:$G$47>0)*(1000000000-Runs!$G$2:$G$47)))))/C14) | G14: =IF(NOT(ISNUMBER(E14)),"No data",IF(ISNUMBER(F14),IF(F14>$C$6,"Repeats disagree: ",""),"")&IF(ABS(E14)<$C$6,"Within noise",IF(E14<0,"Cheaper","Dearer")))
A15: Annual mileage -40% | B15: =COUNTIFS(Runs!$C$2:$C$47,A15,Runs!$G$2:$G$47,">0") | C15: =IFERROR(AVERAGEIFS(Runs!$G$2:$G$47,Runs!$C$2:$C$47,A15),"") | D15: =IF(AND(ISNUMBER(C15),ISNUMBER($C$3)),C15-$C$3,"") | E15: =IF(ISNUMBER(D15),D15/$C$3,"") | F15: =IF(B15<2,"",(SUMPRODUCT(MAX((Runs!$C$2:$C$47=A15)*(Runs!$G$2:$G$47>0)*Runs!$G$2:$G$47))-(1000000000-SUMPRODUCT(MAX((Runs!$C$2:$C$47=A15)*(Runs!$G$2:$G$47>0)*(1000000000-Runs!$G$2:$G$47)))))/C15) | G15: =IF(NOT(ISNUMBER(E15)),"No data",IF(ISNUMBER(F15),IF(F15>$C$6,"Repeats disagree: ",""),"")&IF(ABS(E15)<$C$6,"Within noise",IF(E15<0,"Cheaper","Dearer")))
A16: Annual mileage +40% | B16: =COUNTIFS(Runs!$C$2:$C$47,A16,Runs!$G$2:$G$47,">0") | C16: =IFERROR(AVERAGEIFS(Runs!$G$2:$G$47,Runs!$C$2:$C$47,A16),"") | D16: =IF(AND(ISNUMBER(C16),ISNUMBER($C$3)),C16-$C$3,"") | E16: =IF(ISNUMBER(D16),D16/$C$3,"") | F16: =IF(B16<2,"",(SUMPRODUCT(MAX((Runs!$C$2:$C$47=A16)*(Runs!$G$2:$G$47>0)*Runs!$G$2:$G$47))-(1000000000-SUMPRODUCT(MAX((Runs!$C$2:$C$47=A16)*(Runs!$G$2:$G$47>0)*(1000000000-Runs!$G$2:$G$47)))))/C16) | G16: =IF(NOT(ISNUMBER(E16)),"No data",IF(ISNUMBER(F16),IF(F16>$C$6,"Repeats disagree: ",""),"")&IF(ABS(E16)<$C$6,"Within noise",IF(E16<0,"Cheaper","Dearer")))
A17: Voluntary excess +£250 | B17: =COUNTIFS(Runs!$C$2:$C$47,A17,Runs!$G$2:$G$47,">0") | C17: =IFERROR(AVERAGEIFS(Runs!$G$2:$G$47,Runs!$C$2:$C$47,A17),"") | D17: =IF(AND(ISNUMBER(C17),ISNUMBER($C$3)),C17-$C$3,"") | E17: =IF(ISNUMBER(D17),D17/$C$3,"") | F17: =IF(B17<2,"",(SUMPRODUCT(MAX((Runs!$C$2:$C$47=A17)*(Runs!$G$2:$G$47>0)*Runs!$G$2:$G$47))-(1000000000-SUMPRODUCT(MAX((Runs!$C$2:$C$47=A17)*(Runs!$G$2:$G$47>0)*(1000000000-Runs!$G$2:$G$47)))))/C17) | G17: =IF(NOT(ISNUMBER(E17)),"No data",IF(ISNUMBER(F17),IF(F17>$C$6,"Repeats disagree: ",""),"")&IF(ABS(E17)<$C$6,"Within noise",IF(E17<0,"Cheaper","Dearer")))
A18: Voluntary excess +£500 | B18: =COUNTIFS(Runs!$C$2:$C$47,A18,Runs!$G$2:$G$47,">0") | C18: =IFERROR(AVERAGEIFS(Runs!$G$2:$G$47,Runs!$C$2:$C$47,A18),"") | D18: =IF(AND(ISNUMBER(C18),ISNUMBER($C$3)),C18-$C$3,"") | E18: =IF(ISNUMBER(D18),D18/$C$3,"") | F18: =IF(B18<2,"",(SUMPRODUCT(MAX((Runs!$C$2:$C$47=A18)*(Runs!$G$2:$G$47>0)*Runs!$G$2:$G$47))-(1000000000-SUMPRODUCT(MAX((Runs!$C$2:$C$47=A18)*(Runs!$G$2:$G$47>0)*(1000000000-Runs!$G$2:$G$47)))))/C18) | G18: =IF(NOT(ISNUMBER(E18)),"No data",IF(ISNUMBER(F18),IF(F18>$C$6,"Repeats disagree: ",""),"")&IF(ABS(E18)<$C$6,"Within noise",IF(E18<0,"Cheaper","Dearer")))
A19: Voluntary excess +£1,000 | B19: =COUNTIFS(Runs!$C$2:$C$47,A19,Runs!$G$2:$G$47,">0") | C19: =IFERROR(AVERAGEIFS(Runs!$G$2:$G$47,Runs!$C$2:$C$47,A19),"") | D19: =IF(AND(ISNUMBER(C19),ISNUMBER($C$3)),C19-$C$3,"") | E19: =IF(ISNUMBER(D19),D19/$C$3,"") | F19: =IF(B19<2,"",(SUMPRODUCT(MAX((Runs!$C$2:$C$47=A19)*(Runs!$G$2:$G$47>0)*Runs!$G$2:$G$47))-(1000000000-SUMPRODUCT(MAX((Runs!$C$2:$C$47=A19)*(Runs!$G$2:$G$47>0)*(1000000000-Runs!$G$2:$G$47)))))/C19) | G19: =IF(NOT(ISNUMBER(E19)),"No data",IF(ISNUMBER(F19),IF(F19>$C$6,"Repeats disagree: ",""),"")&IF(ABS(E19)<$C$6,"Within noise",IF(E19<0,"Cheaper","Dearer")))
A20: Cover: third party, fire and theft | B20: =COUNTIFS(Runs!$C$2:$C$47,A20,Runs!$G$2:$G$47,">0") | C20: =IFERROR(AVERAGEIFS(Runs!$G$2:$G$47,Runs!$C$2:$C$47,A20),"") | D20: =IF(AND(ISNUMBER(C20),ISNUMBER($C$3)),C20-$C$3,"") | E20: =IF(ISNUMBER(D20),D20/$C$3,"") | F20: =IF(B20<2,"",(SUMPRODUCT(MAX((Runs!$C$2:$C$47=A20)*(Runs!$G$2:$G$47>0)*Runs!$G$2:$G$47))-(1000000000-SUMPRODUCT(MAX((Runs!$C$2:$C$47=A20)*(Runs!$G$2:$G$47>0)*(1000000000-Runs!$G$2:$G$47)))))/C20) | G20: =IF(NOT(ISNUMBER(E20)),"No data",IF(ISNUMBER(F20),IF(F20>$C$6,"Repeats disagree: ",""),"")&IF(ABS(E20)<$C$6,"Within noise",IF(E20<0,"Cheaper","Dearer")))
A21: Cover: third party only | B21: =COUNTIFS(Runs!$C$2:$C$47,A21,Runs!$G$2:$G$47,">0") | C21: =IFERROR(AVERAGEIFS(Runs!$G$2:$G$47,Runs!$C$2:$C$47,A21),"") | D21: =IF(AND(ISNUMBER(C21),ISNUMBER($C$3)),C21-$C$3,"") | E21: =IF(ISNUMBER(D21),D21/$C$3,"") | F21: =IF(B21<2,"",(SUMPRODUCT(MAX((Runs!$C$2:$C$47=A21)*(Runs!$G$2:$G$47>0)*Runs!$G$2:$G$47))-(1000000000-SUMPRODUCT(MAX((Runs!$C$2:$C$47=A21)*(Runs!$G$2:$G$47>0)*(1000000000-Runs!$G$2:$G$47)))))/C21) | G21: =IF(NOT(ISNUMBER(E21)),"No data",IF(ISNUMBER(F21),IF(F21>$C$6,"Repeats disagree: ",""),"")&IF(ABS(E21)<$C$6,"Within noise",IF(E21<0,"Cheaper","Dearer")))
A22: Black box (telematics) quote | B22: =COUNTIFS(Runs!$C$2:$C$47,A22,Runs!$G$2:$G$47,">0") | C22: =IFERROR(AVERAGEIFS(Runs!$G$2:$G$47,Runs!$C$2:$C$47,A22),"") | D22: =IF(AND(ISNUMBER(C22),ISNUMBER($C$3)),C22-$C$3,"") | E22: =IF(ISNUMBER(D22),D22/$C$3,"") | F22: =IF(B22<2,"",(SUMPRODUCT(MAX((Runs!$C$2:$C$47=A22)*(Runs!$G$2:$G$47>0)*Runs!$G$2:$G$47))-(1000000000-SUMPRODUCT(MAX((Runs!$C$2:$C$47=A22)*(Runs!$G$2:$G$47>0)*(1000000000-Runs!$G$2:$G$47)))))/C22) | G22: =IF(NOT(ISNUMBER(E22)),"No data",IF(ISNUMBER(F22),IF(F22>$C$6,"Repeats disagree: ",""),"")&IF(ABS(E22)<$C$6,"Within noise",IF(E22<0,"Cheaper","Dearer"))) | H22: Record the cheapest black-box price
A23: Start date +1 day | B23: =COUNTIFS(Runs!$C$2:$C$47,A23,Runs!$G$2:$G$47,">0") | C23: =IFERROR(AVERAGEIFS(Runs!$G$2:$G$47,Runs!$C$2:$C$47,A23),"") | D23: =IF(AND(ISNUMBER(C23),ISNUMBER($C$3)),C23-$C$3,"") | E23: =IF(ISNUMBER(D23),D23/$C$3,"") | F23: =IF(B23<2,"",(SUMPRODUCT(MAX((Runs!$C$2:$C$47=A23)*(Runs!$G$2:$G$47>0)*Runs!$G$2:$G$47))-(1000000000-SUMPRODUCT(MAX((Runs!$C$2:$C$47=A23)*(Runs!$G$2:$G$47>0)*(1000000000-Runs!$G$2:$G$47)))))/C23) | G23: =IF(NOT(ISNUMBER(E23)),"No data",IF(ISNUMBER(F23),IF(F23>$C$6,"Repeats disagree: ",""),"")&IF(ABS(E23)<$C$6,"Within noise",IF(E23<0,"Cheaper","Dearer")))
A24: Start date +4 weeks | B24: =COUNTIFS(Runs!$C$2:$C$47,A24,Runs!$G$2:$G$47,">0") | C24: =IFERROR(AVERAGEIFS(Runs!$G$2:$G$47,Runs!$C$2:$C$47,A24),"") | D24: =IF(AND(ISNUMBER(C24),ISNUMBER($C$3)),C24-$C$3,"") | E24: =IF(ISNUMBER(D24),D24/$C$3,"") | F24: =IF(B24<2,"",(SUMPRODUCT(MAX((Runs!$C$2:$C$47=A24)*(Runs!$G$2:$G$47>0)*Runs!$G$2:$G$47))-(1000000000-SUMPRODUCT(MAX((Runs!$C$2:$C$47=A24)*(Runs!$G$2:$G$47>0)*(1000000000-Runs!$G$2:$G$47)))))/C24) | G24: =IF(NOT(ISNUMBER(E24)),"No data",IF(ISNUMBER(F24),IF(F24>$C$6,"Repeats disagree: ",""),"")&IF(ABS(E24)<$C$6,"Within noise",IF(E24<0,"Cheaper","Dearer")))
A25: Pay monthly (record total payable) | B25: =COUNTIFS(Runs!$C$2:$C$47,A25,Runs!$G$2:$G$47,">0") | C25: =IFERROR(AVERAGEIFS(Runs!$G$2:$G$47,Runs!$C$2:$C$47,A25),"") | D25: =IF(AND(ISNUMBER(C25),ISNUMBER($C$3)),C25-$C$3,"") | E25: =IF(ISNUMBER(D25),D25/$C$3,"") | F25: =IF(B25<2,"",(SUMPRODUCT(MAX((Runs!$C$2:$C$47=A25)*(Runs!$G$2:$G$47>0)*Runs!$G$2:$G$47))-(1000000000-SUMPRODUCT(MAX((Runs!$C$2:$C$47=A25)*(Runs!$G$2:$G$47>0)*(1000000000-Runs!$G$2:$G$47)))))/C25) | G25: =IF(NOT(ISNUMBER(E25)),"No data",IF(ISNUMBER(F25),IF(F25>$C$6,"Repeats disagree: ",""),"")&IF(ABS(E25)<$C$6,"Within noise",IF(E25<0,"Cheaper","Dearer"))) | H25: Use total payable over the year
A26: Alternative job title (also true) | B26: =COUNTIFS(Runs!$C$2:$C$47,A26,Runs!$G$2:$G$47,">0") | C26: =IFERROR(AVERAGEIFS(Runs!$G$2:$G$47,Runs!$C$2:$C$47,A26),"") | D26: =IF(AND(ISNUMBER(C26),ISNUMBER($C$3)),C26-$C$3,"") | E26: =IF(ISNUMBER(D26),D26/$C$3,"") | F26: =IF(B26<2,"",(SUMPRODUCT(MAX((Runs!$C$2:$C$47=A26)*(Runs!$G$2:$G$47>0)*Runs!$G$2:$G$47))-(1000000000-SUMPRODUCT(MAX((Runs!$C$2:$C$47=A26)*(Runs!$G$2:$G$47>0)*(1000000000-Runs!$G$2:$G$47)))))/C26) | G26: =IF(NOT(ISNUMBER(E26)),"No data",IF(ISNUMBER(F26),IF(F26>$C$6,"Repeats disagree: ",""),"")&IF(ABS(E26)<$C$6,"Within noise",IF(E26<0,"Cheaper","Dearer"))) | H26: Only a title that is genuinely accurate
A27: Overnight parking: other option | B27: =COUNTIFS(Runs!$C$2:$C$47,A27,Runs!$G$2:$G$47,">0") | C27: =IFERROR(AVERAGEIFS(Runs!$G$2:$G$47,Runs!$C$2:$C$47,A27),"") | D27: =IF(AND(ISNUMBER(C27),ISNUMBER($C$3)),C27-$C$3,"") | E27: =IF(ISNUMBER(D27),D27/$C$3,"") | F27: =IF(B27<2,"",(SUMPRODUCT(MAX((Runs!$C$2:$C$47=A27)*(Runs!$G$2:$G$47>0)*Runs!$G$2:$G$47))-(1000000000-SUMPRODUCT(MAX((Runs!$C$2:$C$47=A27)*(Runs!$G$2:$G$47>0)*(1000000000-Runs!$G$2:$G$47)))))/C27) | G27: =IF(NOT(ISNUMBER(E27)),"No data",IF(ISNUMBER(F27),IF(F27>$C$6,"Repeats disagree: ",""),"")&IF(ABS(E27)<$C$6,"Within noise",IF(E27<0,"Cheaper","Dearer"))) | H27: Only to learn the effect
A28: Name spelling change | B28: =COUNTIFS(Runs!$C$2:$C$47,A28,Runs!$G$2:$G$47,">0") | C28: =IFERROR(AVERAGEIFS(Runs!$G$2:$G$47,Runs!$C$2:$C$47,A28),"") | D28: =IF(AND(ISNUMBER(C28),ISNUMBER($C$3)),C28-$C$3,"") | E28: =IF(ISNUMBER(D28),D28/$C$3,"") | F28: =IF(B28<2,"",(SUMPRODUCT(MAX((Runs!$C$2:$C$47=A28)*(Runs!$G$2:$G$47>0)*Runs!$G$2:$G$47))-(1000000000-SUMPRODUCT(MAX((Runs!$C$2:$C$47=A28)*(Runs!$G$2:$G$47>0)*(1000000000-Runs!$G$2:$G$47)))))/C28) | G28: =IF(NOT(ISNUMBER(E28)),"No data",IF(ISNUMBER(F28),IF(F28>$C$6,"Repeats disagree: ",""),"")&IF(ABS(E28)<$C$6,"Within noise",IF(E28<0,"Cheaper","Dearer"))) | H28: TEST ONLY. Never publish. Never buy.
A29: Middle name added | B29: =COUNTIFS(Runs!$C$2:$C$47,A29,Runs!$G$2:$G$47,">0") | C29: =IFERROR(AVERAGEIFS(Runs!$G$2:$G$47,Runs!$C$2:$C$47,A29),"") | D29: =IF(AND(ISNUMBER(C29),ISNUMBER($C$3)),C29-$C$3,"") | E29: =IF(ISNUMBER(D29),D29/$C$3,"") | F29: =IF(B29<2,"",(SUMPRODUCT(MAX((Runs!$C$2:$C$47=A29)*(Runs!$G$2:$G$47>0)*Runs!$G$2:$G$47))-(1000000000-SUMPRODUCT(MAX((Runs!$C$2:$C$47=A29)*(Runs!$G$2:$G$47>0)*(1000000000-Runs!$G$2:$G$47)))))/C29) | G29: =IF(NOT(ISNUMBER(E29)),"No data",IF(ISNUMBER(F29),IF(F29>$C$6,"Repeats disagree: ",""),"")&IF(ABS(E29)<$C$6,"Within noise",IF(E29<0,"Cheaper","Dearer"))) | H29: TEST ONLY. Never publish. Never buy.
A31: Reading the verdict: 'Within noise' = the gap is smaller than normal run-to-run variation. 'Repeats disagree' = the two runs of the same change differ by more than the noise level, so do not trust that row.

Sheet Profile
A1: Field | B1: Baseline answer (fill in) | C1: Note
A2: Car make, model, engine, gearbox | B2: e.g. VW Polo 1.2 manual | C2: Pick a common car.
A3: Year
A4: Fuel
A5: Value (£) | C5: Use the site's suggested value.
A6: Alarm / immobiliser
A7: Tracker | B7: No | C7: Tested as a change.
A8: Modifications | B8: No
A9: Dashcam
A10: Who owns / registered keeper
A11: Title / first name / surname | B11: DUMMY NAME | C11: Dummy only.
A12: Date of birth | B12: DUMMY | C12: Dummy only. Fix it for every run.
A13: Marital status
A14: Address and postcode area | B14: DUMMY | C14: Dummy. Fix it for every run.
A15: Email / phone | B15: DUMMY | C15: Use a throwaway email.
A16: Occupation / employment | C16: Keep the same wording in every run unless testing job titles.
A17: Years licence held
A18: Cars in household
A19: Children / homeowner
A20: Claims (last 5 years) | B20: None
A21: Convictions | B21: None
A22: Named / additional drivers | B22: None | C22: Tested as a change.
A23: Policy start date | B23: Today + 3 weeks | C23: Same offset every run unless testing the date.
A24: Cover type | B24: Comprehensive
A25: Voluntary excess (£) | B25: 250 | C25: Tested as a change.
A26: Payment | B26: Annual | C26: Tested as a change.
A27: Use / annual mileage
A28: Where kept / overnight
A29: No-claims discount (years)
A30: Comparison site used | C30: Use the SAME site for all runs.
A31: Browser / private window | C31: Private window each run.

Sheet Runs
A1: Run # | B1: Group | C1: Change tested | D1: Date | E1: Time | F1: Site | G1: Cheapest price (£/yr) | H1: Insurer of cheapest | I1: Total excess (£) | J1: 2nd cheapest (£) | K1: Black box? | L1: Notes / what you actually changed | M1: Plan note | N1: Baseline price (helper) | O1: Change vs baseline avg (%)
A2: 1 | B2: Baseline | C2: Baseline | N2: =IF(AND(B2="Baseline",ISNUMBER(G2)),G2,"") | O2: =IF(AND(B2="Change",ISNUMBER(G2),ISNUMBER(Summary!$C$3)),G2/Summary!$C$3-1,"")
A3: 2 | B3: Change | C3: Add parent 1 as a named driver | M3: Only if they would genuinely drive | N3: =IF(AND(B3="Baseline",ISNUMBER(G3)),G3,"") | O3: =IF(AND(B3="Change",ISNUMBER(G3),ISNUMBER(Summary!$C$3)),G3/Summary!$C$3-1,"")
A4: 3 | B4: Change | C4: Add parent 2 as a named driver | M4: Only if they would genuinely drive | N4: =IF(AND(B4="Baseline",ISNUMBER(G4)),G4,"") | O4: =IF(AND(B4="Change",ISNUMBER(G4),ISNUMBER(Summary!$C$3)),G4/Summary!$C$3-1,"")
A5: 4 | B5: Change | C5: Add both parents as named drivers | M5: Only if they would genuinely drive | N5: =IF(AND(B5="Baseline",ISNUMBER(G5)),G5,"") | O5: =IF(AND(B5="Change",ISNUMBER(G5),ISNUMBER(Summary!$C$3)),G5/Summary!$C$3-1,"")
A6: 5 | B6: Change | C6: Vehicle value +10% | N6: =IF(AND(B6="Baseline",ISNUMBER(G6)),G6,"") | O6: =IF(AND(B6="Change",ISNUMBER(G6),ISNUMBER(Summary!$C$3)),G6/Summary!$C$3-1,"")
A7: 6 | B7: Change | C7: Vehicle value -10% | N7: =IF(AND(B7="Baseline",ISNUMBER(G7)),G7,"") | O7: =IF(AND(B7="Change",ISNUMBER(G7),ISNUMBER(Summary!$C$3)),G7/Summary!$C$3-1,"")
A8: 7 | B8: Change | C8: Add a tracker | N8: =IF(AND(B8="Baseline",ISNUMBER(G8)),G8,"") | O8: =IF(AND(B8="Change",ISNUMBER(G8),ISNUMBER(Summary!$C$3)),G8/Summary!$C$3-1,"")
A9: 8 | B9: Change | C9: Annual mileage -40% | N9: =IF(AND(B9="Baseline",ISNUMBER(G9)),G9,"") | O9: =IF(AND(B9="Change",ISNUMBER(G9),ISNUMBER(Summary!$C$3)),G9/Summary!$C$3-1,"")
A10: 9 | B10: Change | C10: Annual mileage +40% | N10: =IF(AND(B10="Baseline",ISNUMBER(G10)),G10,"") | O10: =IF(AND(B10="Change",ISNUMBER(G10),ISNUMBER(Summary!$C$3)),G10/Summary!$C$3-1,"")
A11: 10 | B11: Change | C11: Voluntary excess +£250 | N11: =IF(AND(B11="Baseline",ISNUMBER(G11)),G11,"") | O11: =IF(AND(B11="Change",ISNUMBER(G11),ISNUMBER(Summary!$C$3)),G11/Summary!$C$3-1,"")
A12: 11 | B12: Change | C12: Voluntary excess +£500 | N12: =IF(AND(B12="Baseline",ISNUMBER(G12)),G12,"") | O12: =IF(AND(B12="Change",ISNUMBER(G12),ISNUMBER(Summary!$C$3)),G12/Summary!$C$3-1,"")
A13: 12 | B13: Baseline | C13: Baseline | N13: =IF(AND(B13="Baseline",ISNUMBER(G13)),G13,"") | O13: =IF(AND(B13="Change",ISNUMBER(G13),ISNUMBER(Summary!$C$3)),G13/Summary!$C$3-1,"")
A14: 13 | B14: Change | C14: Voluntary excess +£1,000 | N14: =IF(AND(B14="Baseline",ISNUMBER(G14)),G14,"") | O14: =IF(AND(B14="Change",ISNUMBER(G14),ISNUMBER(Summary!$C$3)),G14/Summary!$C$3-1,"")
A15: 14 | B15: Change | C15: Cover: third party, fire and theft | N15: =IF(AND(B15="Baseline",ISNUMBER(G15)),G15,"") | O15: =IF(AND(B15="Change",ISNUMBER(G15),ISNUMBER(Summary!$C$3)),G15/Summary!$C$3-1,"")
A16: 15 | B16: Change | C16: Cover: third party only | N16: =IF(AND(B16="Baseline",ISNUMBER(G16)),G16,"") | O16: =IF(AND(B16="Change",ISNUMBER(G16),ISNUMBER(Summary!$C$3)),G16/Summary!$C$3-1,"")
A17: 16 | B17: Change | C17: Black box (telematics) quote | M17: Record the cheapest black-box price | N17: =IF(AND(B17="Baseline",ISNUMBER(G17)),G17,"") | O17: =IF(AND(B17="Change",ISNUMBER(G17),ISNUMBER(Summary!$C$3)),G17/Summary!$C$3-1,"")
A18: 17 | B18: Change | C18: Start date +1 day | N18: =IF(AND(B18="Baseline",ISNUMBER(G18)),G18,"") | O18: =IF(AND(B18="Change",ISNUMBER(G18),ISNUMBER(Summary!$C$3)),G18/Summary!$C$3-1,"")
A19: 18 | B19: Change | C19: Start date +4 weeks | N19: =IF(AND(B19="Baseline",ISNUMBER(G19)),G19,"") | O19: =IF(AND(B19="Change",ISNUMBER(G19),ISNUMBER(Summary!$C$3)),G19/Summary!$C$3-1,"")
A20: 19 | B20: Change | C20: Pay monthly (record total payable) | M20: Use total payable over the year | N20: =IF(AND(B20="Baseline",ISNUMBER(G20)),G20,"") | O20: =IF(AND(B20="Change",ISNUMBER(G20),ISNUMBER(Summary!$C$3)),G20/Summary!$C$3-1,"")
A21: 20 | B21: Change | C21: Alternative job title (also true) | M21: Only a title that is genuinely accurate | N21: =IF(AND(B21="Baseline",ISNUMBER(G21)),G21,"") | O21: =IF(AND(B21="Change",ISNUMBER(G21),ISNUMBER(Summary!$C$3)),G21/Summary!$C$3-1,"")
A22: 21 | B22: Change | C22: Overnight parking: other option | M22: Only to learn the effect | N22: =IF(AND(B22="Baseline",ISNUMBER(G22)),G22,"") | O22: =IF(AND(B22="Change",ISNUMBER(G22),ISNUMBER(Summary!$C$3)),G22/Summary!$C$3-1,"")
A23: 22 | B23: Change | C23: Name spelling change | M23: TEST ONLY. Never publish. Never buy. | N23: =IF(AND(B23="Baseline",ISNUMBER(G23)),G23,"") | O23: =IF(AND(B23="Change",ISNUMBER(G23),ISNUMBER(Summary!$C$3)),G23/Summary!$C$3-1,"")
A24: 23 | B24: Change | C24: Middle name added | M24: TEST ONLY. Never publish. Never buy. | N24: =IF(AND(B24="Baseline",ISNUMBER(G24)),G24,"") | O24: =IF(AND(B24="Change",ISNUMBER(G24),ISNUMBER(Summary!$C$3)),G24/Summary!$C$3-1,"")
A25: 24 | B25: Baseline | C25: Baseline | N25: =IF(AND(B25="Baseline",ISNUMBER(G25)),G25,"") | O25: =IF(AND(B25="Change",ISNUMBER(G25),ISNUMBER(Summary!$C$3)),G25/Summary!$C$3-1,"")
A26: 25 | B26: Change | C26: Add parent 1 as a named driver | M26: Only if they would genuinely drive | N26: =IF(AND(B26="Baseline",ISNUMBER(G26)),G26,"") | O26: =IF(AND(B26="Change",ISNUMBER(G26),ISNUMBER(Summary!$C$3)),G26/Summary!$C$3-1,"")
A27: 26 | B27: Change | C27: Add parent 2 as a named driver | M27: Only if they would genuinely drive | N27: =IF(AND(B27="Baseline",ISNUMBER(G27)),G27,"") | O27: =IF(AND(B27="Change",ISNUMBER(G27),ISNUMBER(Summary!$C$3)),G27/Summary!$C$3-1,"")
A28: 27 | B28: Change | C28: Add both parents as named drivers | M28: Only if they would genuinely drive | N28: =IF(AND(B28="Baseline",ISNUMBER(G28)),G28,"") | O28: =IF(AND(B28="Change",ISNUMBER(G28),ISNUMBER(Summary!$C$3)),G28/Summary!$C$3-1,"")
A29: 28 | B29: Change | C29: Vehicle value +10% | N29: =IF(AND(B29="Baseline",ISNUMBER(G29)),G29,"") | O29: =IF(AND(B29="Change",ISNUMBER(G29),ISNUMBER(Summary!$C$3)),G29/Summary!$C$3-1,"")
A30: 29 | B30: Change | C30: Vehicle value -10% | N30: =IF(AND(B30="Baseline",ISNUMBER(G30)),G30,"") | O30: =IF(AND(B30="Change",ISNUMBER(G30),ISNUMBER(Summary!$C$3)),G30/Summary!$C$3-1,"")
A31: 30 | B31: Change | C31: Add a tracker | N31: =IF(AND(B31="Baseline",ISNUMBER(G31)),G31,"") | O31: =IF(AND(B31="Change",ISNUMBER(G31),ISNUMBER(Summary!$C$3)),G31/Summary!$C$3-1,"")
A32: 31 | B32: Change | C32: Annual mileage -40% | N32: =IF(AND(B32="Baseline",ISNUMBER(G32)),G32,"") | O32: =IF(AND(B32="Change",ISNUMBER(G32),ISNUMBER(Summary!$C$3)),G32/Summary!$C$3-1,"")
A33: 32 | B33: Change | C33: Annual mileage +40% | N33: =IF(AND(B33="Baseline",ISNUMBER(G33)),G33,"") | O33: =IF(AND(B33="Change",ISNUMBER(G33),ISNUMBER(Summary!$C$3)),G33/Summary!$C$3-1,"")
A34: 33 | B34: Change | C34: Voluntary excess +£250 | N34: =IF(AND(B34="Baseline",ISNUMBER(G34)),G34,"") | O34: =IF(AND(B34="Change",ISNUMBER(G34),ISNUMBER(Summary!$C$3)),G34/Summary!$C$3-1,"")
A35: 34 | B35: Change | C35: Voluntary excess +£500 | N35: =IF(AND(B35="Baseline",ISNUMBER(G35)),G35,"") | O35: =IF(AND(B35="Change",ISNUMBER(G35),ISNUMBER(Summary!$C$3)),G35/Summary!$C$3-1,"")
A36: 35 | B36: Change | C36: Voluntary excess +£1,000 | N36: =IF(AND(B36="Baseline",ISNUMBER(G36)),G36,"") | O36: =IF(AND(B36="Change",ISNUMBER(G36),ISNUMBER(Summary!$C$3)),G36/Summary!$C$3-1,"")
A37: 36 | B37: Change | C37: Cover: third party, fire and theft | N37: =IF(AND(B37="Baseline",ISNUMBER(G37)),G37,"") | O37: =IF(AND(B37="Change",ISNUMBER(G37),ISNUMBER(Summary!$C$3)),G37/Summary!$C$3-1,"")
A38: 37 | B38: Change | C38: Cover: third party only | N38: =IF(AND(B38="Baseline",ISNUMBER(G38)),G38,"") | O38: =IF(AND(B38="Change",ISNUMBER(G38),ISNUMBER(Summary!$C$3)),G38/Summary!$C$3-1,"")
A39: 38 | B39: Change | C39: Black box (telematics) quote | M39: Record the cheapest black-box price | N39: =IF(AND(B39="Baseline",ISNUMBER(G39)),G39,"") | O39: =IF(AND(B39="Change",ISNUMBER(G39),ISNUMBER(Summary!$C$3)),G39/Summary!$C$3-1,"")
A40: 39 | B40: Change | C40: Start date +1 day | N40: =IF(AND(B40="Baseline",ISNUMBER(G40)),G40,"") | O40: =IF(AND(B40="Change",ISNUMBER(G40),ISNUMBER(Summary!$C$3)),G40/Summary!$C$3-1,"")
...
